Workbook

Sheet precios damian
F1: lista precios | H1: dólar | I1: 1430
A3: DESCRIPCIoN | B3: MARCA | C3: MODELO | D3: PRECIO (USD) | E3: venta en dolares | F3: costo pesos | G3: precio venta PESOS
A4: cough asisst | D4: 6980 | E4: =D4*1.3+10 -> 9084 | G4: =E4*I1 -> 12990120
A5: AUTO CPAP CON HUMIDIFICADOR | B5: BMC | C5: G3 | D5: 518 | E5: =D5*1.3+10 -> 683.4 | F5: =D5*I1 -> 740740 | G5: =E5*I1 -> 977262
A6: BPAP CON HUMIDIFICADOR AVAPS | B6: BMC | C6: G2 | D6: 1.012,00 | E6: =D6*1.3+10 -> 1325.6 | F6: =D6*I1 -> 1447160 | G6: =E6*I1 -> 1895608
A7: bpap con humidificador Y FREC | B7: bmc | C7: g3 | D7: 690 | E7: =D7*1.3+10 -> 907 | G7: =E7*I1 -> 1297010
A8: CONCENTRADOR YUWELL Y BMC | B8: YUWELL | D8: 541 | E8: =D8*1.3+10 -> 713.3 | F8: =E8*1.3+10 -> 937.29 | G8: =E8*I1 -> 1020019
A9: AUTOCPAP CON HUMIDIFICADOR Y MODEM | B9: PHILIPS | C9: DREAMSTATION | D9: 575 | E9: =D9*1.3+10 -> 757.5 | G9: =E9*I1 -> 1083225
A10: TERMOHUMIDIFICADOR | B10: PHILIPS | C10: DREAMSTATION | D10: 144 | E10: =D10*1.3+10 -> 197.2 | G10: =E10*I1 -> 281996
A11: AUTO CPAP CON HUMIDIFICADOR | B11: BMC | C11: G2 | D11: 334 | E11: =D11*1.3+10 -> 444.2 | F11: =D11*I1 -> 477620 | G11: =E11*I1 -> 635206
A12: AUTO CPAP SIN HUMIDIFICADOR | B12: BMC | C12: G2 | D12: 230 | E12: =D12*1.3+10 -> 309 | F12: =D12*I1 -> 328900 | G12: =E12*I1 -> 441870
A13: AUTO CPAP CON HUMIDIFICADOR | B13: BMC | C13: G2S | D13: 311 | E13: =D13*1.3+10 -> 414.3 | F13: =D13*$I$1 -> 444730 | G13: =E13*I1 -> 592449 | H13: 1
A14: AUTO CPAP SIN HUMIDIFICADOR | B14: YUWELL | C14: YH-560 | D14: 402,50 | E14: =D14*1.3+10 -> 533.25 | F14: =D14*$I$1 -> 575575 | G14: =E14*I1 -> 762547.5
A15: AUTO CPAP CON HUMIDIFICADOR | B15: YUWELL | C15: YH-560 | D15: 460,00 | E15: =D15*1.3+10 -> 608 | F15: =D15*$I$1 -> 657800 | G15: =E15*I1 -> 869440 | H15: 1
A16: CPAP CON HUMIDIFICADOR | B16: BMC | C16: G2S | D16: 320,00 | E16: =D16*1.3+10 -> 426 | F16: =D16*$I$1 -> 457600 | G16: =E16*I1 -> 609180 | H16: 1
A17: CPAP CON HUMIDIFICADOR | B17: YAMIND | C17: DM26 | D17: 320,00 | E17: =D17*1.3+10 -> 426 | F17: =D17*$I$1 -> 457600 | G17: =E17*I1 -> 609180
A18: CPAP CON HUMIDIFICADOR | B18: YUWELL | C18: YH-350 | D18: 250 | E18: =D18*1.3+10 -> 335 | F18: =D18*$I$1 -> 357500 | G18: =E18*I1 -> 479050
A19: CPAP CON HUMIDIFICADOR | B19: YUWELL | C19: YH-360 | D19: 305 | E19: =D19*1.3+10 -> 406.5 | F19: =D19*$I$1 -> 436150 | G19: =E19*I1 -> 581295 | H19: 1
A20: CPAP PHILIPS CON MODEM | B20: DREASTATION | D20: 437 | E20: =D20*1.3+10 -> 578.1 | G20: =E20*I1 -> 826683
A21: ASPIRADOR DE SECRESIONES | B21: MOVIVAC | C21: A-550 | D21: 549 | E21: =D21*1.3+10 -> 723.7 | G21: =E21*I1 -> 1034891
A22: CPAP CON HUMIDIFICADOR RESMED MAS NUBE | B22: AIRSENSE | C22: 10 | D22: 466 | E22: =D22*1.3+10 -> 615.8 | F22: =D22*$I$1 -> 666380 | G22: =E22*I1 -> 880594
A23: AUTO CPAP CON HUMIDIFICADOR SIN NUBE RESMED | B23: AIRSENSE | C23: 10 | D23: 690,00 | E23: =D23*1.3+10 -> 907 | F23: =D23*$I$1 -> 986700 | G23: =E23*I1 -> 1297010
A24: AUTO CPAP CON HUMIDIFICADOR CON NUBE RESMED | B24: AIRSENSE | C24: 10 | D24: 633 | E24: =D24*1.3+10 -> 832.9 | F24: =D24*$I$1 -> 905190 | G24: =E24*I1 -> 1191047
A25: AUTOCPAP SIN HUMIDIFICADOR + NASAL N5AH BMC | B25: M1 | C25: MINI | D25: 1070.5 | E25: =D25*1.3+10 -> 1401.65 | F25: =E25*1.3+10 -> 1832.145 | G25: =E25*I1 -> 2004359.5
A26: AUTOCPAP SIN HUMIDIFICADOR + NASAL PILLOW P2H BMC | B26: M1 | C26: MINI | D26: 1070.5 | E26: 1401 | F26: =D26*$I$1 -> -433331470 | G26: =E26*I1 -> 2003430
A27: AUTOCPAP CON HUMIDIFICADOR | B27: PHILIPS | C27: DREAMSTATION | D27: 678,50 | E27: =D27*1.3+10 -> 892.05 | F27: =D27*$I$1 -> 970255 | G27: =E27*I1 -> 1275631.5
A28: BPAP CON HUMIDIFICADOR AVAPS | B28: YUWELL | C28: YH-830 | D28: 759,00 | E28: =D28*1.3+10 -> 996.7 | F28: =D28*$I$1 -> 1085370 | G28: =E28*I1 -> 1425281
A29: BPAP CON HUMIDIFICADOR ST + MASCARA NASAL F2 TALLE M | B29: BMC | C29: G3 | D29: 690 | E29: =D29*1.3+10 -> 907 | F29: =D29*$I$1 -> 986700 | G29: =E29*I1 -> 1297010
A30: CONCENTRADOR DE OXIGENO PORTATIL PHILIPS | B30: SIMPLY | C30: GO | D30: 2.990,00 | E30: =D30*1.3+10 -> 3897 | F30: =D30*$I$1 -> 4275700 | G30: =E30*I1 -> 5572710 | H30: 1
A31: concentrador portatil cont 2L 2 baterias | B31: gce | D31: 2300 | E31: =D31*1.3+10 -> 3000 | G31: =E31*I1 -> 4290000
A32: concentrador portatil cont 2L 2 baterias | B32: gce | D32: 2875 | E32: =D32*1.3+10 -> 3747.5 | G32: =E32*I1 -> 5358925
A33: NASAL S CON APOYA FRENTE | B33: YUWELL | C33: YN-02 | D33: 25,00 | E33: =D33*1.3+10 -> 42.5 | F33: =D33*$I$1 -> 35750 | G33: =E33*I1 -> 60775
A34: NASAL M CON APOYA FRENTE | B34: YUWELL | C34: YN-02 | D34: 25,00 | E34: =D34*1.3+10 -> 42.5 | F34: =D34*$I$1 -> 35750 | G34: =E34*I1 -> 60775
A35: NASAL L CON APOYA FRENTE | B35: YUWELL | C35: YN-02 | D35: 25,00 | E35: =D35*1.3+10 -> 42.5 | F35: =D35*$I$1 -> 35750 | G35: =E35*I1 -> 60775
A36: NASAL L M S SIN APOYA FRENTE | B36: YUWELL | C36: YN-03 | D36: 32 | E36: =D36*1.3+10 -> 51.6 | G36: =E36*I1 -> 73788
A37: BUCONASAL S | B37: YUWELL | C37: YF-01 | D37: 28,00 | E37: =D37*1.3+10 -> 46.4 | F37: =D37*$I$1 -> 40040 | G37: =E37*I1 -> 66352
A38: BUCONASAL M | B38: YUWELL | C38: YF-01 | D38: 28,00 | E38: =D38*1.3+10 -> 46.4 | F38: =D38*$I$1 -> 40040 | G38: =E38*I1 -> 66352
A39: BUCONASAL L | B39: YUWELL | C39: YF-01 | D39: 28,00 | E39: =D39*1.3+10 -> 46.4 | F39: =D39*$I$1 -> 40040 | G39: =E39*I1 -> 66352
A40: BUCONASAL S | B40: YUWELL | C40: YF-02 | D40: 32,00 | E40: =D40*1.3+10 -> 51.6 | F40: =D40*$I$1 -> 45760 | G40: =E40*I1 -> 73788
A41: BUCONASAL M | B41: YUWELL | C41: YF-02 | D41: 32,00 | E41: =D41*1.3+10 -> 51.6 | F41: =D41*$I$1 -> 45760 | G41: =E41*I1 -> 73788
...

Sheet precios mark
A1: Producto | B1: Precio (USD) | C1: IVA | E1: precio venta dolares | F1: VENTA EN PESOS | G1: VALOR DOLAR | H1: 1485
A2: concentrador portatil Kingon p2-e 1 litro 5 niveles | B2: 1650 | C2: 1.105 | D2: =B2*C2 -> 1823.25 | E2: =D2*1.3+10 -> 2380.225 | F2: =E2*H1 -> 3534634.1
A3: Concentrador portatil Kingon P2-S3. (1,8 kg.; 0,62 litros/min; 3 niveles pulsado) | B3: 1300 | C3: 1.105 | D3: =B3*C3 -> 1436.5 | E3: =D3*1.3+10 -> 1877.45 | F3: =E3*H1 -> 2788013.2
A4: concentrador portatil Kingon p2-e6 1,2 litro 6 niveles | B4: 1850 | C4: 1.105 | D4: =B4*C4 -> 2044.25 | E4: =D4*1.3+10 -> 2667.525 | F4: =E4*H1 -> 3961274.6
A5: concentrador portatil kingon p2-e7 1,4 litros 7 niveles | B5: 2150 | C5: 1.105 | D5: =B5*C5 -> 2375.75 | E5: =D5*1.3+10 -> 3098.475 | F5: =E5*H1 -> 4601235.4
A6: Concentrador portatil Kingon P2-TOC (8 kg.; carrito | B6: 2400 | C6: 1.105 | D6: =B6*C6 -> 2652 | E6: =D6*1.3+10 -> 3457.6 | F6: =E6*H1 -> 5134536
A7: BATERIA KINGON P2-tOC | B7: 550 | C7: 1.105 | D7: =B7*C7 -> 607.75 | E7: =D7*1.3+10 -> 800.075 | F7: =E7*H1 -> 1188111.4
A9: bateria kingon | B9: 290 | C9: 1.105 | D9: =B9*C9 -> 320.45 | E9: =D9*1.3+10 -> 426.585 | F9: =E9*H1 -> 633478.72
A10: mochila kingon | B10: 120 | C10: 1.21 | D10: =B10*C10 -> 145.2 | E10: =D10*1.3+10 -> 198.76 | F10: =E10*H1 -> 295158.6
A12: filtro kingon 5 unidades | B12: 16 | C12: =B12*1.21 -> 19.36 | D12: =B12*C12 -> 309.76 | E12: =D12*1.3+10 -> 412.688 | F12: =E12*H1 -> 612841.68
A13: CONCENTRADOR ESTACIONARIO MICITECH | B13: 520 | C13: 1.105 | D13: =B13*C13 -> 574.6 | E13: =D13*1.3+10 -> 756.98 | F13: =E13*H1 -> 1124115.3
A14: CPAP Topson | B14: 260 | C14: 1.105 | D14: =B14*C14 -> 287.3 | E14: =D14*1.3+10 -> 383.49 | F14: =E14*H1 -> 569482.65
A15: CPAP + Humidificador Topson | B15: 270 | C15: 1.105 | D15: =B15*C15 -> 298.35 | E15: =D15*1.3+10 -> 397.855 | F15: =E15*H1 -> 590814.68
A16: AUTOCPAP Topson | B16: 330 | C16: 1.105 | D16: =B16*C16 -> 364.65 | E16: =D16*1.3+10 -> 484.045 | F16: =E16*H1 -> 718806.82
A17: AUTOCPAP + Humidificador Topson | B17: 340 | C17: 1.105 | D17: =B17*C17 -> 375.7 | E17: =D17*1.3+10 -> 498.41 | F17: =E17*H1 -> 740138.85
A18: BPAP + Humidificador Topson | B18: 850 | C18: 1.105 | D18: =B18*C18 -> 939.25 | E18: =D18*1.3+10 -> 1231.025 | F18: =E18*H1 -> 1828072.1
A19: AUTOBPAP + Humidificador Topson | B19: 900 | C19: 1.105 | D19: =B19*C19 -> 994.5 | E19: =D19*1.3+10 -> 1302.85 | F19: =E19*H1 -> 1934732.2
A20: BPAP con Frecuencia + Humidificador Topson | B20: 950 | C20: 1.105 | D20: =B20*C20 -> 1049.75 | E20: =D20*1.3+10 -> 1374.675 | F20: =E20*H1 -> 2041392.4
A21: BPAP AVAPS 25 + Humidificador Topson | B21: 1000 | C21: 1.105 | D21: =B21*C21 -> 1105 | E21: =D21*1.3+10 -> 1446.5 | F21: =E21*H1 -> 2148052.5
A22: BPAP AVAPS 30 + Humidificador Topson | B22: 1200 | C22: 1.105 | D22: =B22*C22 -> 1326 | E22: =D22*1.3+10 -> 1733.8 | F22: =E22*H1 -> 2574693
A23: BPAP AVAPS 35 + Humidificador Topson | B23: 1300 | C23: 1.105 | D23: =B23*C23 -> 1436.5 | E23: =D23*1.3+10 -> 1877.45 | F23: =E23*H1 -> 2788013.2
A24: Humidificador Topson (incluye carcasa reusable) | B24: 50 | C24: 1.21 | D24: =B24*C24 -> 60.5 | E24: =D24*1.3+10 -> 88.65 | F24: =E24*H1 -> 131645.25
A25: Carcasa reusable para humidificador | B25: 30 | C25: 1.21 | D25: =B25*C25 -> 36.3 | E25: =D25*1.3+10 -> 57.19 | F25: =E25*H1 -> 84927.15
A26: Tubladura 22 mm premium Topson | B26: 14 | C26: 1.21 | D26: =B26*C26 -> 16.94 | E26: =D26*1.3 -> 22.022 | F26: =E26*H1 -> 32702.67
A27: Tubladura 15 mm premium Topson | B27: 18 | C27: 1.21 | D27: =B27*C27 -> 21.78 | E27: =D27*1.3 -> 28.314 | F27: =E27*H1 -> 42046.29
A28: Filtro exterior Topson | B28: 2.8 | C28: 1.21 | D28: =B28*C28 -> 3.388 | E28: =D28*1.3+10 -> 14.4044 | F28: =E28*H1 -> 21390.534
A29: HSINER 821 (S, M, L) | B29: 27 | C29: 1.21 | D29: =B29*C29 -> 32.67 | E29: =D29*1.3+10 -> 52.471 | F29: =E29*H1 -> 77919.435
A30: HSINER 825 (S, M, L) | B30: 27 | C30: 1.21 | D30: =B30*C30 -> 32.67 | E30: =D30*1.3+10 -> 52.471 | F30: =E30*H1 -> 77919.435
A31: HSINER Comfo plus (S, M, L) | B31: 33 | C31: 1.21 | D31: =B31*C31 -> 39.93 | E31: =D31*1.3+10 -> 61.909 | F31: =E31*H1 -> 91934.865
A32: HSINER 843 (S, M, L) | B32: 36 | C32: 1.21 | D32: =B32*C32 -> 43.56 | E32: =D32*1.3+10 -> 66.628 | F32: =E32*H1 -> 98942.58
A33: YUWELL YN-02 (S, M, L) | B33: 27 | C33: 1.21 | D33: =B33*C33 -> 32.67 | E33: =D33*1.3+10 -> 52.471 | F33: =E33*H1 -> 77919.435
A34: YUWELL YN-03 (S, M, L) | B34: 36 | C34: 1.21 | D34: =B34*C34 -> 43.56 | E34: =D34*1.3+10 -> 66.628 | F34: =E34*H1 -> 98942.58
A35: HSINER 101 (4 talles incluidos) | B35: 60 | C35: 1.21 | D35: =B35*C35 -> 72.6 | E35: =D35*1.3+10 -> 104.38 | F35: =E35*H1 -> 155004.3
A36: YUWELL YP-01 (3 talles incluidos) | B36: 60 | C36: 1.21 | D36: =B36*C36 -> 72.6 | E36: =D36*1.3+10 -> 104.38 | F36: =E36*H1 -> 155004.3
A37: HSINER 825 (S, M, L) | B37: 36 | C37: 1.21 | D37: =B37*C37 -> 43.56 | E37: =D37*1.3+10 -> 66.628 | F37: =E37*H1 -> 98942.58
A38: HSINER Comfo (S, M, L) | B38: 36 | C38: 1.21 | D38: =B38*C38 -> 43.56 | E38: =D38*1.3+10 -> 66.628 | F38: =E38*H1 -> 98942.58
A39: YUWELL YF-01 (S, M, L) | B39: 36 | C39: 1.21 | D39: =B39*C39 -> 43.56 | E39: =D39*1.3+10 -> 66.628 | F39: =E39*H1 -> 98942.58
A40: YUWELL YF-02 (S, M, L) | B40: 40 | C40: 1.21 | D40: =B40*C40 -> 48.4 | E40: =D40*1.3+10 -> 72.92 | F40: =E40*H1 -> 108286.2
A41: Nasal HSINER Cirri Mini (S, M, L, XS) | B41: 60 | C41: 1.21 | D41: =B41*C41 -> 72.6 | E41: =D41*1.3+10 -> 104.38 | F41: =E41*H1 -> 155004.3 | G41: 1
B42: 70 | C42: 1.21 | D42: =B42*C42 -> 84.7 | E42: =D42*1.3+10 -> 120.11 | F42: =E42*H1 -> 178363.35
...

Sheet stock mascaras
A1: Marca | B1: Modelo | C1: Talle | D1: Stock | E1: precio
B2: NASALES
A3: RESCOM M | B3: NASAL CON APOYA | C3: M | D3: 2 | E3: ='precios damian'!G94 -> 46475
A4: RESCOM | C4: L | D4: 1
A5: DRAGER | D5: 1
A6: DREAMWEAR | B6: NASAL | D6: 1 | E6: ='precios damian'!G47 -> 218790
A7: BMC | B7: N2 NASAL CON APOYA | C7: M | D7: 1 | E7: ='precios damian'!G61 -> 51308.4
A8: BMC | B8: N4 NASAL CON APOYA | C8: S | D8: 1 | E8: ='precios damian'!G59 -> 71929
A9: BMC | B9: N5 NASAL CON APOYA | C9: L | D9: 1 | E9: ='precios damian'!G63 -> 57721.95
A10: BMC | B10: N5A NASAL SIN APOYA | C10: M | D10: 2 | E10: ='precios damian'!G72 -> 84942
A11: BMC | B11: N5A NASAL SIN APOYA | C11: L | D11: 1 | E11: ='precios damian'!G73 -> 84942
A12: YUWELL | B12: YN 03 NASAL SIN APOYA | C12: S | D12: 0 | E12: ='precios damian'!G25 -> 2004359.5
A13: HSINER | B13: NASAL CON APOYA CHILD | C13: L | D13: 0
A14: HSINER | B14: NASAL CON APOYA | C14: M | D14: 0
A15: HSINER | B15: NASAL CHILD | C15: M | D15: 0 | E15: ='precios mark'!F41 -> 155004.3
A16: DRAGUERS | B16: NASAL CON APOYA | C16: M | D16: 0 | E16: ='precios damian'!G107 -> 65608.4
A17: YUWELL | B17: YN 02 NASAL CON APOYA | C17: M | D17: 4 | E17: ='precios damian'!G33 -> 60775
A18: YUWELL | B18: YN 03 NASAL SIN APOYA | C18: S | D18: 1 | E18: ='precios damian'!G36 -> 73788
B20: FACIALES | D20: 0
A21: HSINER | B21: FACIAL CON APOYA | C21: M | D21: 0
A22: HSINER FACIAL CON APOYA M 2 | C22: M | D22: 0
A23: HSINER | B23: FACIAL CON APOYA | C23: M | D23: 0
A24: YUWELL | B24: YF 02 FULLFACE SIN APOYA | C24: L | D24: 1 | E24: ='precios damian'!G40 -> 73788
A25: YUWELL | B25: YF 02 FULLFACE SIN APOYA | C25: S | D25: 0 | E25: ='precios damian'!G41 -> 73788
A26: YEWELL | B26: YF 02 FULLFACE SIN APOYA | C26: M | D26: 1 | E26: =E25 -> 73788
A27: BMC | B27: F5A FULL FACE SIN APOYA | C27: S | D27: 1 | E27: ='precios damian'!G76 -> 73788
A28: BMC | B28: F2 FULL FACE CON APOYA | C28: M | D28: 2 | E28: ='precios damian'!G56 -> 66352
A29: bmc | B29: f6 simil dreamwear | C29: s,m,l | D29: 1 | E29: ='precios damian'!G77 -> 192764
A30: DREAMWEAR | B30: nasobucal L | D30: 1 | E30: ='precios damian'!G48 -> 224367
D31: 0
